Workbook

Sheet INSTRUCCIONES
A1: ESG DATA COLLECTION TEMPLATE
A2: GHG Protocol — Scope 1, 2 & 3 | Completar en AZUL | No modificar celdas en NEGRO o VERDE
A4: HOJAS
A5: [EN] 1. EMPRESA | B5: [EN] Datos generales de la organización — completar primero
A6: [EN] 2. SCOPE_1 | B6: [EN] Emisiones directas: combustibles, flota, refrigerantes
A7: [EN] 3. SCOPE_2 | B7: [EN] Electricidad y energía comprada
A8: [EN] 4. SCOPE_3 | B8: [EN] Cadena de valor: proveedores, flete, viajes, commuting
A9: [EN] 5. RESULTADOS | B9: [EN] Cálculos automáticos — NO modificar
A11: CONVENCIÓN DE COLORES
A12: [EN] Celda AMARILLA | B12: [EN] Dato que vos completás — ingresá el número aquí
A13: [EN] Texto AZUL | B13: [EN] Inputs que ingresan el usuario (vos)
A14: [EN] Texto NEGRO | B14: [EN] Fórmulas calculadas automáticamente — no tocar
A15: [EN] Texto VERDE | B15: [EN] Links a otras hojas — no tocar
A17: INSTRUCCIONES
A18: [EN] Paso 1 | B18: [EN] Completar hoja EMPRESA con los datos generales
A19: [EN] Paso 2 | B19: [EN] Completar SCOPE_1: consumos de combustible y refrigerantes del año
A20: [EN] Paso 3 | B20: [EN] Completar SCOPE_2: facturas de electricidad por sede
A21: [EN] Paso 4 | B21: [EN] Completar SCOPE_3: gastos proveedores, fletes, viajes y encuesta commuting
A22: [EN] Paso 5 | B22: [EN] Ver hoja RESULTADOS para el inventario GHG consolidado
A24: FUENTES
A25: [EN] Factores combustible | B25: [EN] IPCC AR6 (2021) — kgCO2e por litro
A26: [EN] Factores electricidad | B26: [EN] IEA Emissions Factors (2023) — kgCO2e por kWh
A27: [EN] Factores Scope 3 Cat1 | B27: [EN] EEIO adaptado a LatAm — kgCO2e por USD gastado
A28: [EN] Factores transporte | B28: [EN] GLEC Framework v3 — kgCO2e por tonelada-km
A29: [EN] Factores viajes | B29: [EN] DEFRA 2023 — kgCO2e por pasajero-km

Sheet EMPRESA
A1: DATOS GENERALES DE LA EMPRESA
A2: Completar todas las celdas en AMARILLO
A3: IDENTIFICACIÓN
A4: [EN] Nombre legal de la empresa | C4: [EN] Razón social completa
A5: [EN] País principal de operación | C5: [EN] Argentina / Chile / Peru / Brasil / Mexico / Colombia
A6: [EN] Año fiscal del reporte | B6: 2024 | C6: [EN] Ej: 2024
A7: [EN] Período (mes inicio) | B7: [EN] Enero | C7: [EN] Ej: Enero
A8: [EN] Período (mes fin) | B8: [EN] Diciembre | C8: [EN] Ej: Diciembre
A9: TAMAÑO
A10: [EN] Cantidad de empleados (promedio anual) | C10: [EN] Número entero
A11: [EN] Revenue anual (USD) | C11: [EN] En dólares estadounidenses
A12: [EN] Revenue anual (moneda local) | C12: [EN] En moneda local
A13: [EN] Número de sedes / instalaciones | C13: [EN] Número entero
A14: SECTOR
A15: [EN] Sector principal | C15: [EN] Manufactura / Retail / Servicios / Energía / Tecnología / Otro
A16: [EN] Subsector | C16: [EN] Descripción específica
A17: [EN] ¿Tienen reporte ESG anterior? | C17: [EN] Sí / No
A18: [EN] Framework ESG anterior (si aplica) | C18: [EN] GRI / TCFD / IFRS S1/S2 / Otro
A19: CONTEXTO REGULATORIO
A20: [EN] ¿Listados en bolsa? | C20: [EN] Sí / No — indicar bolsa
A21: [EN] ¿Inversores o bancos piden datos ESG? | C21: [EN] Sí / No
A22: [EN] ¿Sujetos a impuesto al carbono? | C22: [EN] Sí / No
A23: [EN] País(es) adicionales de operación | C23: [EN] Separar con comas si hay varios

Sheet SCOPE_1
A1: SCOPE 1 — EMISIONES DIRECTAS
A2: FACTORES DE EMISIÓN UTILIZADOS (IPCC AR6)
A3: [EN] Combustible | B3: [EN] Factor (kgCO2e/litro) | C3: [EN] Fuente
A4: [EN] Gasoil / Diesel | B4: 2.68 | C4: [EN] IPCC AR6
A5: [EN] Nafta / Gasolina | B5: 2.31 | C5: [EN] IPCC AR6
A6: [EN] GLP / Propano | B6: 1.51 | C6: [EN] IPCC AR6
A7: [EN] GNC (kgCO2e/m³) | B7: 2.02 | C7: [EN] IPCC AR6
A8: [EN] Fuel Oil | B8: 3.17 | C8: [EN] IPCC AR6
A10: A. CONSUMO DE COMBUSTIBLES — completar en litros (o m³ para GNC)
A11: [EN] Fuente / Instalación | B11: [EN] Tipo combustible | C11: [EN] Consumo anual | D11: [EN] Unidad | E11: [EN] Factor kgCO2e/unidad | F11: [EN] tCO2e calculado | G11: [EN] Notas
A12: [EN] Flota vehículos propios | B12: [EN] Gasoil | D12: [EN] litros | E12: 2.68 | F12: =IF(C12="","",IF(ISNUMBER(C12),C12*E12/1000,""))
A13: [EN] Generadores / emergencia | B13: [EN] Gasoil | D13: [EN] litros | E13: 2.68 | F13: =IF(C13="","",IF(ISNUMBER(C13),C13*E13/1000,""))
A14: [EN] Calderas / calefacción | B14: [EN] Gas Natural | D14: [EN] m³ | E14: 2.02 | F14: =IF(C14="","",IF(ISNUMBER(C14),C14*E14/1000,""))
A15: [EN] Maquinaria de producción | B15: [EN] Gasoil | D15: [EN] litros | E15: 2.68 | F15: =IF(C15="","",IF(ISNUMBER(C15),C15*E15/1000,""))
A16: [EN] Vehículos livianos | B16: [EN] Nafta | D16: [EN] litros | E16: 2.31 | F16: =IF(C16="","",IF(ISNUMBER(C16),C16*E16/1000,""))
A17: [EN] Otro — especificar en Notas | D17: [EN] litros | F17: =IF(C17="","",IF(AND(ISNUMBER(C17),ISNUMBER(E17)),C17*E17/1000,""))
A18: TOTAL Scope 1 — Combustibles (tCO2e) | F18: =SUM(F12:F17)
A20: B. REFRIGERANTES (HFCs) — sistemas de aire acondicionado y refrigeración
A21: [EN] Equipo / Sistema | B21: [EN] Tipo de gas | C21: [EN] Recarga anual (kg) | D21: [EN] GWP (CO2e/kg) | E21: [EN] Factor | F21: [EN] tCO2e | G21: [EN] Notas
A22: [EN] Aire acondicionado oficinas | B22: [EN] R-410A | D22: 2088 | E22: 2088 | F22: =IF(C22="","",IF(AND(ISNUMBER(C22),ISNUMBER(E22)),C22*E22/1000,""))
A23: [EN] Cámaras frigoríficas | B23: [EN] R-134a | D23: 1430 | E23: 1430 | F23: =IF(C23="","",IF(AND(ISNUMBER(C23),ISNUMBER(E23)),C23*E23/1000,""))
A24: [EN] Equipos industriales | B24: [EN] R-404A | D24: 3922 | E24: 3922 | F24: =IF(C24="","",IF(AND(ISNUMBER(C24),ISNUMBER(E24)),C24*E24/1000,""))
A25: [EN] Otro refrigerante | F25: =IF(C25="","",IF(AND(ISNUMBER(C25),ISNUMBER(E25)),C25*E25/1000,""))
A26: TOTAL Scope 1 — Refrigerantes (tCO2e) | F26: =SUM(F22:F25)
A28: TOTAL SCOPE 1 (tCO2e) | F28: =F18+F26

Sheet SCOPE_2
A1: SCOPE 2 — ELECTRICIDAD Y ENERGÍA COMPRADA
A2: FACTORES DE RED ELÉCTRICA (IEA 2023) — kgCO2e por kWh
A3: [EN] País | B3: [EN] Factor location-based | C3: [EN] Factor market-based* | D3: [EN] Notas
A4: [EN] Argentina | B4: 0.321 | C4: 0.321 | D4: [EN] Red SADI
A5: [EN] Chile | B5: 0.295 | C5: 0.295 | D5: [EN] Sistema SEN
A6: [EN] Perú | B6: 0.247 | C6: 0.247 | D6: [EN] SEIN
A7: [EN] Brasil | B7: 0.075 | C7: 0.075 | D7: [EN] SIN — alta renovable
A8: [EN] Colombia | B8: 0.126 | C8: 0.126 | D8: [EN] SIN
A9: [EN] México | B9: 0.454 | C9: 0.454 | D9: [EN] SEN
A12: CONSUMO DE ELECTRICIDAD — una fila por sede/instalación
A13: [EN] Sede / Instalación | B13: [EN] País | C13: [EN] Consumo anual (kWh) | D13: [EN] Factor kgCO2e/kWh | E13: [EN] ¿Energía renovable? | F13: [EN] tCO2e | G13: [EN] Fuente del dato
A14: [EN] Casa central / oficina principal | B14: [EN] Argentina | D14: 0.321 | E14: [EN] No | F14: =IF(C14="","",IF(AND(ISNUMBER(C14),ISNUMBER(D14)),IF(E14="Sí",0,C14*D14/1000),"")) | G14: [EN] Facturas eléctricas
A15: [EN] Planta de producción | B15: [EN] Argentina | D15: 0.321 | E15: [EN] No | F15: =IF(C15="","",IF(AND(ISNUMBER(C15),ISNUMBER(D15)),IF(E15="Sí",0,C15*D15/1000),"")) | G15: [EN] Facturas eléctricas
A16: [EN] Depósito / logística | B16: [EN] Argentina | D16: 0.321 | E16: [EN] No | F16: =IF(C16="","",IF(AND(ISNUMBER(C16),ISNUMBER(D16)),IF(E16="Sí",0,C16*D16/1000),"")) | G16: [EN] Facturas eléctricas
A17: [EN] Sede Chile (si aplica) | B17: [EN] Chile | D17: 0.295 | E17: [EN] No | F17: =IF(C17="","",IF(AND(ISNUMBER(C17),ISNUMBER(D17)),IF(E17="Sí",0,C17*D17/1000),"")) | G17: [EN] Facturas eléctricas
A18: [EN] Sede Perú (si aplica) | B18: [EN] Perú | D18: 0.247 | E18: [EN] No | F18: =IF(C18="","",IF(AND(ISNUMBER(C18),ISNUMBER(D18)),IF(E18="Sí",0,C18*D18/1000),"")) | G18: [EN] Facturas eléctricas
A19: [EN] Otra sede — especificar | F19: =IF(C19="","",IF(AND(ISNUMBER(C19),ISNUMBER(D19)),IF(E19="Sí",0,C19*D19/1000),"")) | G19: [EN] Facturas eléctricas
A20: [EN] Otra sede — especificar | F20: =IF(C20="","",IF(AND(ISNUMBER(C20),ISNUMBER(D20)),IF(E20="Sí",0,C20*D20/1000),"")) | G20: [EN] Facturas eléctricas
A21: TOTAL SCOPE 2 (tCO2e) | F21: =SUM(F14:F20)
A22: * Si tienen certificados de energía renovable (RECs / i-RECs), el factor market-based puede ser 0. Indicar en columna E.

Sheet SCOPE_3
A1: SCOPE 3 — CADENA DE VALOR
A2: CAT. 1 — BIENES Y SERVICIOS COMPRADOS (método spend-based)
A3: [EN] Categoría de proveedor | B3: [EN] Gasto anual (USD) | C3: [EN] Factor kgCO2e/USD | D3: [EN] tCO2e | E3: [EN] % del total de compras | F3: [EN] Top proveedor | G3: [EN] Gasto proveedor (USD) | H3: [EN] Notas
A4: [EN] Manufactura / producción | C4: 0.45 | D4: =IF(B4="","",IF(ISNUMBER(B4),B4*C4/1000,"")) | E4: =IF(B4="","",IF(SUM(B4:B12)>0,B4/SUM(B4:B12),""))
A5: [EN] Energía / utilities | C5: 0.68 | D5: =IF(B5="","",IF(ISNUMBER(B5),B5*C5/1000,"")) | E5: =IF(B5="","",IF(SUM(B4:B12)>0,B5/SUM(B4:B12),""))
A6: [EN] Transporte / logística | C6: 0.41 | D6: =IF(B6="","",IF(ISNUMBER(B6),B6*C6/1000,"")) | E6: =IF(B6="","",IF(SUM(B4:B12)>0,B6/SUM(B4:B12),""))
A7: [EN] Servicios profesionales | C7: 0.18 | D7: =IF(B7="","",IF(ISNUMBER(B7),B7*C7/1000,"")) | E7: =IF(B7="","",IF(SUM(B4:B12)>0,B7/SUM(B4:B12),""))
A8: [EN] Tecnología / software | C8: 0.22 | D8: =IF(B8="","",IF(ISNUMBER(B8),B8*C8/1000,"")) | E8: =IF(B8="","",IF(SUM(B4:B12)>0,B8/SUM(B4:B12),""))
A9: [EN] Construcción / infraestr. | C9: 0.38 | D9: =IF(B9="","",IF(ISNUMBER(B9),B9*C9/1000,"")) | E9: =IF(B9="","",IF(SUM(B4:B12)>0,B9/SUM(B4:B12),""))
A10: [EN] Alimentos / insumos agro | C10: 0.52 | D10: =IF(B10="","",IF(ISNUMBER(B10),B10*C10/1000,"")) | E10: =IF(B10="","",IF(SUM(B4:B12)>0,B10/SUM(B4:B12),""))
A11: [EN] Retail / packaging | C11: 0.25 | D11: =IF(B11="","",IF(ISNUMBER(B11),B11*C11/1000,"")) | E11: =IF(B11="","",IF(SUM(B4:B12)>0,B11/SUM(B4:B12),""))
A12: [EN] Otro — especificar | C12: 0.3 | D12: =IF(B12="","",IF(ISNUMBER(B12),B12*C12/1000,"")) | E12: =IF(B12="","",IF(SUM(B4:B12)>0,B12/SUM(B4:B12),""))
A13: TOTAL Cat. 1 (tCO2e) | D13: =SUM(D4:D12)
A15: CAT. 4 — TRANSPORTE UPSTREAM (fletes entrantes)
A16: [EN] Tramo / Proveedor | B16: [EN] Modo transporte | C16: [EN] Toneladas | D16: [EN] Km promedio | E16: [EN] Factor (kgCO2e/t-km) | F16: [EN] tCO2e | H16: [EN] Notas
A17: [EN] Proveedores locales (camión) | B17: [EN] Camión | E17: 0.062 | F17: =IF(OR(C17="",D17=""),"",IF(AND(ISNUMBER(C17),ISNUMBER(D17),ISNUMBER(E17)),C17*D17*E17/1000,""))
A18: [EN] Importaciones (barco) | B18: [EN] Barco | E18: 0.008 | F18: =IF(OR(C18="",D18=""),"",IF(AND(ISNUMBER(C18),ISNUMBER(D18),ISNUMBER(E18)),C18*D18*E18/1000,""))
A19: [EN] Importaciones (avión) | B19: [EN] Avión carga | E19: 0.602 | F19: =IF(OR(C19="",D19=""),"",IF(AND(ISNUMBER(C19),ISNUMBER(D19),ISNUMBER(E19)),C19*D19*E19/1000,""))
A20: [EN] Distribución interna (tren) | B20: [EN] Tren | E20: 0.022 | F20: =IF(OR(C20="",D20=""),"",IF(AND(ISNUMBER(C20),ISNUMBER(D20),ISNUMBER(E20)),C20*D20*E20/1000,""))
A21: [EN] Otro tramo | F21: =IF(OR(C21="",D21=""),"",IF(AND(ISNUMBER(C21),ISNUMBER(D21),ISNUMBER(E21)),C21*D21*E21/1000,""))
A22: TOTAL Cat. 4 (tCO2e) | F22: =SUM(F17:F21)
A24: CAT. 6 — VIAJES DE NEGOCIO
A25: [EN] Tipo de viaje | B25: [EN] Modo | C25: [EN] N° de viajes | D25: [EN] Km promedio | E25: [EN] Factor (kgCO2e/pax-km) | F25: [EN] tCO2e | H25: [EN] Notas
A26: [EN] Vuelos nacionales / regionales | B26: [EN] Avión corto | E26: 0.255 | F26: =IF(OR(C26="",D26=""),"",IF(AND(ISNUMBER(C26),ISNUMBER(D26),ISNUMBER(E26)),C26*D26*E26/1000,""))
A27: [EN] Vuelos internacionales | B27: [EN] Avión largo | E27: 0.195 | F27: =IF(OR(C27="",D27=""),"",IF(AND(ISNUMBER(C27),ISNUMBER(D27),ISNUMBER(E27)),C27*D27*E27/1000,""))
A28: [EN] Viajes en auto / remis | B28: [EN] Auto | E28: 0.171 | F28: =IF(OR(C28="",D28=""),"",IF(AND(ISNUMBER(C28),ISNUMBER(D28),ISNUMBER(E28)),C28*D28*E28/1000,""))
A29: [EN] Viajes en bus | B29: [EN] Bus | E29: 0.027 | F29: =IF(OR(C29="",D29=""),"",IF(AND(ISNUMBER(C29),ISNUMBER(D29),ISNUMBER(E29)),C29*D29*E29/1000,""))
A30: [EN] Viajes en tren | B30: [EN] Tren | E30: 0.041 | F30: =IF(OR(C30="",D30=""),"",IF(AND(ISNUMBER(C30),ISNUMBER(D30),ISNUMBER(E30)),C30*D30*E30/1000,""))
A31: TOTAL Cat. 6 (tCO2e) | F31: =SUM(F26:F30)
A33: CAT. 7 — TRANSPORTE DE EMPLEADOS (commuting) | 220 días laborales, 25 km/día promedio
A34: [EN] Modo de transporte | B34: [EN] % empleados (completar) | C34: [EN] Empleados (calc.) | D34: [EN] km/día | E34: [EN] Días/año | F34: [EN] Factor (kgCO2e/km) | G34: [EN] tCO2e | H34: [EN] Notas
A35: [EN] Auto solo | C35: =IF(ISNUMBER(B35),B35*EMPRESA!B8,"") | D35: 25 | E35: 220 | F35: 0.171 | G35: =IF(C35="","",IF(ISNUMBER(C35),C35*D35*E35*F35/1000,""))
A36: [EN] Auto compartido (2) | C36: =IF(ISNUMBER(B36),B36*EMPRESA!B8,"") | D36: 25 | E36: 220 | F36: 0.085 | G36: =IF(C36="","",IF(ISNUMBER(C36),C36*D36*E36*F36/1000,""))
A37: [EN] Colectivo / bus | C37: =IF(ISNUMBER(B37),B37*EMPRESA!B8,"") | D37: 25 | E37: 220 | F37: 0.027 | G37: =IF(C37="","",IF(ISNUMBER(C37),C37*D37*E37*F37/1000,""))
A38: [EN] Subte / metro | C38: =IF(ISNUMBER(B38),B38*EMPRESA!B8,"") | D38: 25 | E38: 220 | F38: 0.011 | G38: =IF(C38="","",IF(ISNUMBER(C38),C38*D38*E38*F38/1000,""))
A39: [EN] Moto | C39: =IF(ISNUMBER(B39),B39*EMPRESA!B8,"") | D39: 25 | E39: 220 | F39: 0.103 | G39: =IF(C39="","",IF(ISNUMBER(C39),C39*D39*E39*F39/1000,""))
A40: [EN] Bicicleta | C40: =IF(ISNUMBER(B40),B40*EMPRESA!B8,"") | D40: 25 | E40: 220 | F40: 0 | G40: =IF(C40="","",IF(ISNUMBER(C40),C40*D40*E40*F40/1000,""))
A41: [EN] Caminando | C41: =IF(ISNUMBER(B41),B41*EMPRESA!B8,"") | D41: 25 | E41: 220 | F41: 0 | G41: =IF(C41="","",IF(ISNUMBER(C41),C41*D41*E41*F41/1000,""))
A42: [EN] Home office (no viaja) | C42: =IF(ISNUMBER(B42),B42*EMPRESA!B8,"") | D42: 0 | E42: 0 | F42: 0 | G42: =IF(C42="","",IF(ISNUMBER(C42),C42*D42*E42*F42/1000,""))
A43: TOTAL Cat. 7 (tCO2e) | G43: =SUM(G35:G42)
...

Sheet RESULTADOS
A1: INVENTARIO GHG — RESULTADOS CONSOLIDADOS
A2: NO MODIFICAR ESTA HOJA — los datos vienen automáticamente de las hojas anteriores
A4: DATOS DE LA EMPRESA
A5: [EN] Empresa | B5: =EMPRESA!B4
A6: [EN] País | B6: =EMPRESA!B5
A7: [EN] Año | B7: =EMPRESA!B6
A8: [EN] Empleados | B8: =EMPRESA!B8
A9: [EN] Revenue (USD) | B9: =EMPRESA!B9
A10: [EN] Sector | B10: =EMPRESA!B13
A12: INVENTARIO GHG COMPLETO
A13: [EN] Categoría | B13: [EN] tCO2e | C13: [EN] % del total | D13: [EN] Método | E13: [EN] Fuente datos
A14: [EN] Scope 1 — Combustibles | B14: =SCOPE_1!F18 | C14: =IF(B14="","",IF(B21>0,B14/B21,"")) | D14: [EN] Tier 2 IPCC AR6 | E14: [EN] Facturas / registros de consumo
A15: [EN] Scope 1 — Refrigerantes | B15: =SCOPE_1!F26 | C15: =IF(B15="","",IF(B21>0,B15/B21,"")) | D15: [EN] GWP IPCC AR6 | E15: [EN] Registros de recarga
A16: [EN] Scope 2 — Electricidad | B16: =SCOPE_2!F21 | C16: =IF(B16="","",IF(B21>0,B16/B21,"")) | D16: [EN] Location-based IEA | E16: [EN] Facturas eléctricas
A17: [EN] Scope 3 Cat.1 — Proveedores | B17: =SCOPE_3!D13 | C17: =IF(B17="","",IF(B21>0,B17/B21,"")) | D17: [EN] Spend-based EEIO | E17: [EN] Sistema contable
A18: [EN] Scope 3 Cat.4 — Flete | B18: =SCOPE_3!F22 | C18: =IF(B18="","",IF(B21>0,B18/B21,"")) | D18: [EN] GLEC Framework v3 | E18: [EN] Registros de transporte
A19: [EN] Scope 3 Cat.6 — Viajes | B19: =SCOPE_3!F31 | C19: =IF(B19="","",IF(B21>0,B19/B21,"")) | D19: [EN] DEFRA 2023 | E19: [EN] Sistema HR / gastos
A20: [EN] Scope 3 Cat.7 — Commuting | B20: =SCOPE_3!G43 | C20: =IF(B20="","",IF(B21>0,B20/B21,"")) | D20: [EN] DEFRA 2023 | E20: [EN] Encuesta empleados
A21: TOTAL GENERAL (tCO2e) | B21: =SUM(B14:B20)
A22: Total Scope 1 (tCO2e) | B22: =B14+B15
A23: Total Scope 2 (tCO2e) | B23: =B16
A24: Total Scope 3 (tCO2e) | B24: =SUM(B17:B20)
A26: INDICADORES DE INTENSIDAD
A27: [EN] Indicador | B27: [EN] Valor | C27: [EN] Unidad
A28: [EN] Emisiones por empleado | B28: =IF(AND(ISNUMBER(B21),ISNUMBER(EMPRESA!B8)),B21/EMPRESA!B8,"") | C28: [EN] tCO2e / empleado
A29: [EN] Emisiones por USD 1M revenue | B29: =IF(AND(ISNUMBER(B21),ISNUMBER(EMPRESA!B9)),B21/(EMPRESA!B9/1000000),"") | C29: [EN] tCO2e / USD 1M
A30: [EN] % Scope 3 del total | B30: =IF(AND(ISNUMBER(B24),ISNUMBER(B21)),B24/B21,"") | C30: [EN] %
A31: [EN] % Scope 1+2 del total | B31: =IF(AND(ISNUMBER(B22),ISNUMBER(B23),ISNUMBER(B21)),(B22+B23)/B21,"") | C31: [EN] %
